<?xml version='1.0' encoding='UTF-8'?>
<robot name="four_wheel_robot">
  <link name="chassis">
    <inertial>
      <origin xyz="0.0 0.0 0.0" rpy="0.0 -0.0 0.0"/>
      <mass value="1.0"/>
      <inertia ixx="1.0" ixy="0.0" ixz="0.0" iyy="1.0" iyz="0.0" izz="1.0"/>
    </inertial>
    <visual>
      <geometry>
        <box size="0.5 0.5 0.5"/>
      </geometry>
      <material name="chassis_color"/>
      <origin xyz="0.0 0.0 0.0" rpy="0.0 -0.0 0.0"/>
    </visual>
    <collision name="chassis_collision">
      <geometry>
        <box size="0.5 0.5 0.5"/>
      </geometry>
      <origin xyz="0.0 0.0 0.0" rpy="0.0 -0.0 0.0"/>
    </collision>
  </link>
  <link name="left_front_wheel">
    <inertial>
      <origin xyz="0.0 0.0 0.0" rpy="0.0 -0.0 0.0"/>
      <mass value="1.0"/>
      <inertia ixx="1.0" ixy="0.0" ixz="0.0" iyy="1.0" iyz="0.0" izz="1.0"/>
    </inertial>
    <visual name="&lt;urdfpy.urdf.Material object at 0x7fc969743460&gt;">
      <geometry>
        <cylinder radius="1.0" length="1.0"/>
      </geometry>
      <origin xyz="0.0 0.0 0.0" rpy="0.0 -0.0 0.0"/>
    </visual>
    <collision name="wheel_collision">
      <geometry>
        <cylinder radius="1.0" length="1.0"/>
      </geometry>
      <origin xyz="0.0 0.0 0.0" rpy="0.0 -0.0 0.0"/>
    </collision>
  </link>
  <link name="right_front_wheel">
    <inertial>
      <origin xyz="0.0 0.0 0.0" rpy="0.0 -0.0 0.0"/>
      <mass value="1.0"/>
      <inertia ixx="1.0" ixy="0.0" ixz="0.0" iyy="1.0" iyz="0.0" izz="1.0"/>
    </inertial>
    <visual name="&lt;urdfpy.urdf.Material object at 0x7fc9697439d0&gt;">
      <geometry>
        <cylinder radius="1.0" length="1.0"/>
      </geometry>
      <origin xyz="0.0 0.0 0.0" rpy="0.0 -0.0 0.0"/>
    </visual>
    <collision name="wheel_collision">
      <geometry>
        <cylinder radius="1.0" length="1.0"/>
      </geometry>
      <origin xyz="0.0 0.0 0.0" rpy="0.0 -0.0 0.0"/>
    </collision>
  </link>
  <link name="left_rear_wheel">
    <inertial>
      <origin xyz="0.0 0.0 0.0" rpy="0.0 -0.0 0.0"/>
      <mass value="1.0"/>
      <inertia ixx="1.0" ixy="0.0" ixz="0.0" iyy="1.0" iyz="0.0" izz="1.0"/>
    </inertial>
    <visual name="&lt;urdfpy.urdf.Material object at 0x7fc969743c40&gt;">
      <geometry>
        <cylinder radius="1.0" length="1.0"/>
      </geometry>
      <origin xyz="0.0 0.0 0.0" rpy="0.0 -0.0 0.0"/>
    </visual>
    <collision name="wheel_collision">
      <geometry>
        <cylinder radius="1.0" length="1.0"/>
      </geometry>
      <origin xyz="0.0 0.0 0.0" rpy="0.0 -0.0 0.0"/>
    </collision>
  </link>
  <link name="right_rear_wheel">
    <inertial>
      <origin xyz="0.0 0.0 0.0" rpy="0.0 -0.0 0.0"/>
      <mass value="1.0"/>
      <inertia ixx="1.0" ixy="0.0" ixz="0.0" iyy="1.0" iyz="0.0" izz="1.0"/>
    </inertial>
    <visual name="&lt;urdfpy.urdf.Material object at 0x7fc969743f10&gt;">
      <geometry>
        <cylinder radius="1.0" length="1.0"/>
      </geometry>
      <origin xyz="0.0 0.0 0.0" rpy="0.0 -0.0 0.0"/>
    </visual>
    <collision name="wheel_collision">
      <geometry>
        <cylinder radius="1.0" length="1.0"/>
      </geometry>
      <origin xyz="0.0 0.0 0.0" rpy="0.0 -0.0 0.0"/>
    </collision>
  </link>
  <joint name="left_front_wheel_joint" type="revolute">
    <limit effort="1.0" velocity="1.0"/>
    <parent link="chassis"/>
    <child link="left_front_wheel"/>
    <axis xyz="1. 0. 0."/>
    <origin xyz="0.25 0.25 0.0" rpy="0.0 0.0 0.0"/>
  </joint>
  <joint name="right_front_wheel_joint" type="revolute">
    <limit effort="1.0" velocity="1.0"/>
    <parent link="chassis"/>
    <child link="right_front_wheel"/>
    <axis xyz="1. 0. 0."/>
    <origin xyz="1.0 0.25 0.0" rpy="0.0 0.0 0.0"/>
  </joint>
  <joint name="left_rear_wheel_joint" type="revolute">
    <limit effort="1.0" velocity="1.0"/>
    <parent link="chassis"/>
    <child link="left_rear_wheel"/>
    <axis xyz="1. 0. 0."/>
    <origin xyz="0.0 0.0 0.0" rpy="0.0 -0.0 0.0"/>
  </joint>
  <joint name="right_rear_wheel_joint" type="revolute">
    <limit effort="1.0" velocity="1.0"/>
    <parent link="chassis"/>
    <child link="right_rear_wheel"/>
    <axis xyz="1. 0. 0."/>
    <origin xyz="0.0 0.0 0.0" rpy="0.0 -0.0 0.0"/>
  </joint>
  <material name="chassis_color"/>
</robot>
